Workbook
Name \B: #REF!
Name \B: #REF!
Name \B: #REF!
Name \B: #REF!
Name \B: #REF!
Name \B: #REF!
Name \B: #REF!
Name \B: #REF!
Name \B: #REF!
Name \B: #REF!
Name \B: #REF!
Name \B: #REF!
Name \B: #REF!
Name \B: #REF!
Name \B: #REF!
Name \B: #REF!
Name \B: #REF!
Name \B: #REF!
Name \B: #REF!
Name \B: #REF!
Name \B: #REF!
Name \B: #REF!
Name \B: #REF!
Name \B: #REF!
Name \B: #REF!
Name \B: #REF!
Name \B: #REF!
Name \B: #REF!
Name \B: #REF!
Name \B: #REF!
Name \B: #REF!
Name \B: #REF!
Name \B: #REF!
Name \B: #REF!
Name \B: #REF!
Name \B: #REF!
Name \B: #REF!
Name \B: #REF!
Name \B: #REF!
Name \B: #REF!
Name \B: #REF!
Name \B: #REF!
Name \B: #REF!
Name \B: #REF!
Name \B: #REF!
Name \B: #REF!
Name \B: #REF!
Name \B: #REF!
Name \B: #REF!
Name \B: #REF!
Name \C: #REF!
Name \C: #REF!
Name \C: #REF!
Name \C: #REF!
Name \C: #REF!
Name \C: #REF!
Name \C: #REF!
Name \C: #REF!
Name \C: #REF!
Name \C: #REF!

Sheet Tapioca Starch Price_1
A2: Date | B2: Domestic Price | C2: Date | D2: FOB Bangkok | E2: FOB Hochiminh-Lowest price | F2: FOB Hochiminh-Highest price
A4: 42745 | B4: 11.2 | C4: 42745 | D4: 340
A5: 42752 | B5: 11.2 | C5: 42752 | D5: 340
A6: 42759 | B6: 11 | C6: 42759 | D6: 340
A7: 42766 | B7: 11 | C7: 42766 | D7: 340
A8: 42773 | B8: 11 | C8: 42773 | D8: 340
A9: 42780 | B9: 11 | C9: 42780 | D9: 340
A10: 42787 | B10: 11 | C10: 42787 | D10: 340
A11: 42794 | B11: 11 | C11: 42794 | D11: 340
A12: 42801 | B12: 11.2 | C12: 42801 | D12: 345
A13: 42808 | B13: 11.2 | C13: 42808 | D13: 345
A14: 42815 | B14: 11.2 | C14: 42815 | D14: 345
A15: 42822 | B15: 11.2 | C15: 42822 | D15: 345
... A262: 44558 | B262: 15.1 | C262: 44558 | D262: 490
A263: 44565 | B263: 15.1 | C263: 44565 | D263: 490 | E263: 520 | F263: 540
A264: 44572 | B264: 15.1 | C264: 44572 | D264: 490
A265: 44579 | B265: 15.1 | C265: 44579 | D265: 490
A266: 44586 | B266: 15.1 | C266: 44586 | D266: 490
A267: 44593 | B267: 15.1 | C267: 44593 | D267: 490
A268: 44600 | B268: 15.1 | C268: 44600 | D268: 490
A269: 44607 | B269: 15.1 | C269: 44607 | D269: 495
A270: 44614 | B270: 15.1 | C270: 44614 | D270: 495
A271: 44621 | B271: 15.1 | C271: 44621 | D271: 495
A272: 44628 | B272: 15.15 | C272: 44628 | D272: 495
A273: 44635 | B273: 15.2 | C273: 44635 | D273: 495
A274: 44642 | B274: 15.25 | C274: 44642 | D274: 495
A275: 44649 | B275: 15.35 | C275: 44649 | D275: 495
A276: 44656 | B276: 15.5 | C276: 44656 | D276: 500 | E276: 530 | F276: 560
A277: 44663 | B277: 15.6 | C277: 44663 | D277: 500
A278: 44670 | B278: 15.65 | C278: 44670 | D278: 505
A279: 44677 | B279: 16.1 | C279: 44677 | D279: 510
A280: 44684 | B280: 16.5 | C280: 44684 | D280: 515
A281: 44691 | B281: 16.8 | C281: 44691 | D281: 520
A282: 44698 | B282: 17 | C282: 44698 | D282: 525
A283: 44705 | B283: 17.3 | C283: 44705 | D283: 535
A284: 44712 | B284: 17.35 | C284: 44712 | D284: 540
A285: 44719 | B285: 17.4 | C285: 44719 | D285: 540
A286: 44726 | B286: 17.5 | C286: 44726 | D286: 540
A287: 44733 | B287: 17.5 | C287: 44733 | D287: 540
A288: 44740 | B288: 17.5 | C288: 44740 | D288: 540
...

Sheet Tapioca Production_1
B2: Thailand Tapioca Production
B3: Crop Year | C3: Yield | D3: Crop Year | E3: Plant Area | F3: Production
B4: (October-September) | C4: (Ton/Rai) | D4: (October-September) | E4: (Rai) | F4: (Ton)
B5: 2005/2006 | C5: 3.375 | D5: 2005/2006 | E5: 6692537 | F5: 22584402
B6: 2006/2007 | C6: 3.668 | D6: 2006/2007 | E6: 7201243 | F6: 26411233
B7: 2007/2008 | C7: 3.401 | D7: 2007/2008 | E7: 7397098 | F7: 25155797
B8: 2008/2009 | C8: 3.628 | D8: 2008/2009 | E8: 8292146 | F8: 30088024
B9: 2009/2010 | C9: 3.013 | D9: 2009/2010 | E9: 7302839 | F9: 22005740
B10: 2010/2011 | C10: 3.088 | D10: 2010/2011 | E10: 7096173 | F10: 21912416
B11: 2011/2012 | C11: 3.362 | D11: 2011/2012 | E11: 7911323 | F11: 26601090
B12: 2012/2013 | C12: 3.474 | D12: 2012/2013 | E12: 8138953 | F12: 28275565
B13: 2013/2014 | C13: 3.492 | D13: 2013/2014 | E13: 8656942 | F13: 30227542
B14: 2014/2015 | C14: 3.864 | D14: 2014/2015 | E14: 8697948 | F14: 33610487
B15: 2015/2016 | C15: 3.426 | D15: 2015/2016 | E15: 8919803 | F15: 30557857
B16: 2016/2017 | C16: 3.472 | D16: 2016/2017 | E16: 8910021 | F16: 30935529
... B24: 2024/2025 | C24: 2.958 | D24: 2024/2025 | E24: 8445471 | F24: 24983311
B25: 2025/2026 | D25: 2025/2026 | F25: 18000000
B26: 2026/2076 | D26: 2026/2027

Sheet Tapioca Chip Price_1
A2: Date | B2: (THB/kg) | C2: TH @Srichang Port (USD/MT) | D2: VN to China (USD/MT) | E2: VN to Korea (USD/MT)
A3: 44927 | B3: 8.75 | C3: 269
A4: 44958 | B4: 9 | C4: 275
A5: 44986 | B5: 9.18 | C5: 273
A6: 45017 | B6: 9.38 | C6: 270
A7: 45047 | B7: 9.55 | C7: 266
A8: 45078 | B8: 9.45 | C8: 263
A9: 45108 | B9: 9.35 | C9: 265
A10: 45139 | B10: 9.6 | C10: 273
A11: 45170 | B11: 9.75 | C11: 280
A12: 45200 | B12: 9.68 | C12: 283
A13: 45231 | B13: 9.8 | C13: 278
A14: 45261 | B14: 9.7 | C14: 269
... A26: 45627 | B26: 6.5 | C26: 190
A27: 45658
A28: 45689
A29: 45717
A30: 45748 | B30: 5.45 | C30: 185
A31: 45755 | B31: 5.48 | C31: 185
A32: 45764 | B32: 5.48 | C32: 185
A33: 45769 | B33: 5.53 | C33: 185
A34: 45771 | B34: 5.53 | C34: 185
A35: 45776 | B35: 5.53 | C35: 185
A36: 45785 | B36: 5.58 | C36: 185
A37: 45792 | B37: 5.63 | C37: 192.5
A38: 45797 | B38: 5.63 | C38: 192.5
A39: 45804 | B39: 5.63 | C39: 197.5
A40: 45813 | B40: 5.88 | C40: 197.5
A41: 45818 | B41: 5.88 | C41: 205
... A68: 46007 | B68: 6.13 | C68: 212.5
A69: 46014 | B69: 6.28 | C69: 212.5 | D69: 235 | E69: 290
A70: 46028 | B70: 6.28 | C70: 217.5 | D70: 240 | E70: 295
A71: 46035 | B71: 6.18 | C71: 217.5 | D71: 240 | E71: 295
A72: 46042 | B72: 6.18 | C72: 217.5 | D72: 240 | E72: 295
A73: 46049 | B73: 6.18 | C73: 217.5 | D73: 240 | E73: 295
A74: 46056 | B74: 6.18 | C74: 217.5 | D74: 240 | E74: 295
A75: 46063 | B75: 6.45 | C75: 222.5 | D75: 240 | E75: 295
A76: 46070 | B76: 6.5 | C76: 227.5 | D76: 240 | E76: 295
A77: 46077 | B77: 6.5 | C77: 227.5 | D77: 240 | E77: 295
A78: 46086 | B78: 6.6 | C78: 235 | D78: 250 | E78: 305
...

Sheet Ethanol Price_1
B2: Ethanol (THB./Liter)
B3: Month | C3: THB./Liter
B4: 43101 | C4: 24.57
B5: 43132 | C5: 24.45
B6: 43160 | C6: 24.44
B7: 43191 | C7: 23.59
B8: 43221 | C8: 23.59
B9: 43252 | C9: 23.59
B10: 43282 | C10: 23.4
B11: 43313 | C11: 23.4
B12: 43344 | C12: 23.4
B13: 43374 | C13: 23.31
B14: 43405 | C14: 23.31
B15: 43435 | C15: 23.31
... B27: 43800 | C27: 22.04
B28: 43831 | C28: =AVERAGE(C16:C27) -> 22.0725
B29: 43862 | C29: 22.61
B30: 43891 | C30: 22.61
B31: 43922 | C31: 22.61
B32: 43952 | C32: 23.28
B33: 43983 | C33: 23.28
B34: 44013 | C34: 23.28
B35: 44044 | C35: 23.16
B36: 44075 | C36: 23.16
B37: 44105 | C37: 23.16
B38: 44136 | C38: 23.8
B39: 44166 | C39: 23.8
B40: 44197 | C40: 24.83
... B70: 45474 | C70: 30.52
B71: 45505
B72: 45536
B73: 45566
B74: 45597
B75: 45627
B76: 45658
B77: 45689
B78: 45717
B79: 45748 | C79: 19.38
B80: 45778 | C80: 19.37
B81: 45809 | C81: 19.39
...

Sheet Dry Pulp Monthly price_1
B2: Market dry pulp price
A3: Jan'24 | B3: 4.6
A4: Feb'24 | B4: 4.2041667
A5: Mar'24 | B5: 3.7980769
A6: Apr'24 | B6: 3.24
A7: May'24 | B7: 3.2
A8: Jun'24 | B8: 3.2
A9: Jul'24 | B9: 3.2
A10: Aug'24 | B10: 3.2
A11: Sep'24 | B11: 3.0153846
A12: Oct'24 | B12: 2.6653846
A13: Nov'24 | B13: 2.4230769
A14: Dec'24 | B14: 2.3125
... A31: May'26 | B31: 5.5

Sheet Dry Pulp Daily price_1
A1: Date | B1: Start | C1: End | D1: Average | F1: https://www.nettathai.org/2012-02-06-06-49-09.html
A2: 44501 | B2: =4.5 -> 4.5 | D2: =AVERAGE(B2:C2) -> 4.5
A3: 44503 | B3: =4.5 -> 4.5 | D3: =AVERAGE(B3:C3) -> 4.5
A4: 44505 | B4: =4.5 -> 4.5 | D4: =AVERAGE(B4:C4) -> 4.5
A5: 44508 | B5: =4.5 -> 4.5 | D5: =AVERAGE(B5:C5) -> 4.5
A6: 44510 | B6: =4.5 -> 4.5 | D6: =AVERAGE(B6:C6) -> 4.5
A7: 44512 | B7: =4.5 -> 4.5 | D7: =AVERAGE(B7:C7) -> 4.5
A8: 44515 | B8: 4.5 | C8: 4.6 | D8: =AVERAGE(B8:C8) -> 4.55
A9: 44517 | B9: 4.5 | C9: 4.6 | D9: =AVERAGE(B9:C9) -> 4.55
A10: 44519 | B10: 4.5 | C10: 4.6 | D10: =AVERAGE(B10:C10) -> 4.55
A11: 44522 | B11: 4.5 | C11: 4.6 | D11: =AVERAGE(B11:C11) -> 4.55
A12: 44524 | B12: 4.5 | C12: 4.6 | D12: =AVERAGE(B12:C12) -> 4.55
A13: 44526 | B13: 4.5 | C13: 4.6 | D13: =AVERAGE(B13:C13) -> 4.55
A14: 44529 | B14: 4.5 | C14: 4.6 | D14: =AVERAGE(B14:C14) -> 4.55
A15: 44531 | B15: 4.6 | D15: =AVERAGE(B15:C15) -> 4.6
A16: 44533 | B16: 4.6 | D16: =AVERAGE(B16:C16) -> 4.6
A17: 44536 | B17: 4.5 | C17: 4.6 | D17: =AVERAGE(B17:C17) -> 4.55
A18: 44538 | B18: 4.5 | C18: 4.6 | D18: =AVERAGE(B18:C18) -> 4.55
A19: 44540 | B19: 4.5 | C19: 4.6 | D19: =AVERAGE(B19:C19) -> 4.55
A20: 44543 | B20: 4.5 | C20: 4.6 | D20: =AVERAGE(B20:C20) -> 4.55
A21: 44545 | B21: 4.5 | C21: 4.6 | D21: =AVERAGE(B21:C21) -> 4.55
A22: 44547 | B22: 4.5 | C22: 4.6 | D22: =AVERAGE(B22:C22) -> 4.55
A23: 44550 | B23: 4.5 | C23: 4.6 | D23: =AVERAGE(B23:C23) -> 4.55
A24: 44552 | B24: 4.5 | C24: 4.6 | D24: =AVERAGE(B24:C24) -> 4.55
A25: 44554 | B25: 4.5 | C25: 4.6 | D25: =AVERAGE(B25:C25) -> 4.55
A26: 44557 | B26: 4.5 | C26: 4.6 | D26: =AVERAGE(B26:C26) -> 4.55
A27: 44559 | B27: 4.6 | D27: =AVERAGE(B27:C27) -> 4.6
A28: 5/12022 | B28: 4.5 | C28: 4.6 | D28: =AVERAGE(B28:C28) -> 4.55
A29: 44568 | B29: 4.5 | C29: 4.6 | D29: =AVERAGE(B29:C29) -> 4.55
A30: 44571 | B30: 4.5 | C30: 4.6 | D30: =AVERAGE(B30:C30) -> 4.55
A31: 44573 | B31: 4.5 | C31: 4.6 | D31: =AVERAGE(B31:C31) -> 4.55
A32: 44575 | B32: 4.5 | C32: 4.6 | D32: =AVERAGE(B32:C32) -> 4.55
A33: 44578 | B33: 4.5 | C33: 4.6 | D33: =AVERAGE(B33:C33) -> 4.55
A34: 44580 | B34: 4.5 | C34: 4.6 | D34: =AVERAGE(B34:C34) -> 4.55
A35: 44582 | B35: 4.5 | C35: 4.6 | D35: =AVERAGE(B35:C35) -> 4.55
A36: 44585 | B36: 4.6 | D36: =AVERAGE(B36:C36) -> 4.6
A37: 44587 | B37: 4.6 | C37: 4.8 | D37: =AVERAGE(B37:C37) -> 4.7
A38: 44589 | B38: 4.6 | C38: 4.8 | D38: =AVERAGE(B38:C38) -> 4.7
A39: 44592 | B39: 4.5 | C39: 4.6 | D39: =AVERAGE(B39:C39) -> 4.55
A40: 44594 | B40: 4.5 | C40: 4.6 | D40: =AVERAGE(B40:C40) -> 4.55
...

Sheet LE02026 cost LV11022026_Origi
A1: LE02026 Cost projection E1 (LV:11/2/2026)
A3: SK plant | B3: Jan | C3: Feb | D3: Mar | E3: Apr | F3: May | G3: Jun | H3: Jul | I3: Aug | J3: Sep | K3: Oct | L3: Nov | M3: Dec | N3: Total/Avg.
A5: Day operation | B5: 27 | C5: 28 | D5: 31 | E5: 24 | F5: 31 | G5: 30 | H5: 30 | I5: 31 | J5: 30 | K5: 31 | L5: 30 | M5: 26 | N5: =SUM(B5:M5) -> 349
A6: Grinding/day without waxy | B6: =B7/B5 -> 1088.8185 | C6: =C7/C5 -> 1401.25 | D6: =D7/D5 -> 1551.6129 | E6: =E7/E5 -> 1252.0833 | F6: =F7/F5 -> 1538.7097 | G6: =G7/G5 -> 1410 | H6: =H7/H5 -> 1393.3333 | I6: =I7/I5 -> 1345.1613 | ... N6: =N7/N5 -> 1337.0576
A7: Grinding/month , tons | B7: 29398.1 | C7: 39235 | D7: 48100 | E7: 30050 | F7: 47700 | G7: 42300 | H7: 41800 | I7: 41700 | J7: 39700 | K7: 38700 | L7: 37350 | M7: 30600 | N7: =SUM(B7:M7) -> 466633.1
A9: Roots purchased/month , tons | B9: 29954.31 | C9: 41200 | D9: 48100 | E9: 30050 | F9: 47700 | G9: 42300 | H9: 41800 | I9: 41700 | J9: 39700 | K9: 38700 | L9: 37350 | M9: 30600 | N9: =SUM(B9:M9) -> 469154.31
A10: Starch content , % | B10: 27.073368 | C10: 27.256311 | D10: ='[60]SK MAP - Mar 2026 (2)'!G13 -> 25.742204 | E10: ='[60]SK MAP - Apr 2026 (2)'!G13 -> 22 | F10: ='[60]SK MAP - May 2026 (2)'!G13 -> 20.43501 | G10: ='[60]SK MAP - Jun 2026 (2)'!G13 -> 20.858156 | H10: ='[60]SK MAP - Jul 2026 (2)'!G13 -> 21.5 | I10: ='[60]SK MAP - Aug 2026 (2)'!G13 -> 22.977698 | J10: ='[60]SK MAP - Sep 26 (2)'!G13 -> 23.924433 | K10: ='[60]SK MAP - Oct 26 (2)'!G13 -> 24.503876 | L10: ='[60]SK MAP - Nov 26 (2)'!G13 -> 25.989759 | M10: ='[60]SK MAP - Dec 26 (2)'!G13 -> 26.745098 | N10: =N14/(N9*1000)*100 -> 23.945984
A11: Price , THB/kg. | B11: 2.8182197 | C11: 2.8494175 | D11: ='[60]SK MAP - Mar 2026 (2)'!H13 -> 2.9097713 | E11: ='[60]SK MAP - Apr 2026 (2)'!H13 -> 2.9020799 | F11: ='[60]SK MAP - May 2026 (2)'!H13 -> 2.8197589 | G11: ='[60]SK MAP - Jun 2026 (2)'!H13 -> 2.8361702 | H11: ='[60]SK MAP - Jul 2026 (2)'!H13 -> 2.781244 | I11: ='[60]SK MAP - Aug 2026 (2)'!H13 -> 2.8942446 | J11: ='[60]SK MAP - Sep 26 (2)'!H13 -> 2.9433249 | K11: ='[60]SK MAP - Oct 26 (2)'!H13 -> 2.9290698 | L11: ='[60]SK MAP - Nov 26 (2)'!H13 -> 3.0487952 | M11: ='[60]SK MAP - Dec 26 (2)'!H13 -> 3.0852941 | N11: =N15/(N9*1000) -> 2.8964613 | R11: Actual 2025
A12: PPDS , THB/kg. | B12: =B11/B10*100 -> 10.409564 | C12: =C11/C10*100 -> 10.454157 | D12: =D11/D10*100 -> 11.303505 | E12: =E11/E10*100 -> 13.191272 | F12: =F11/F10*100 -> 13.798666 | G12: =G11/G10*100 -> 13.597416 | H12: =H11/H10*100 -> 12.936019 | I12: =I11/I10*100 -> 12.595886 | ... N12: =N11/N10*100 -> 12.095813 | P12: =#REF! -> #REF! | R12: =#REF! -> #REF!
A14: Weight starch , kg | B14: =((B9*1000)*B10)/100 -> 8109640.5 | C14: =((C9*1000)*C10)/100 -> 11229600 | D14: =((D9*1000)*D10)/100 -> 12382000 | E14: =((E9*1000)*E10)/100 -> 6611000 | F14: =((F9*1000)*F10)/100 -> 9747500 | G14: =((G9*1000)*G10)/100 -> 8823000 | H14: =((H9*1000)*H10)/100 -> 8987000 | I14: =((I9*1000)*I10)/100 -> 9581700 | ... M14: =((M9*1000)*M10)/100 -> 8184000 | N14: =SUM(B14:M14) -> 1.1234362e+08
A15: Amount , THB | B15: =(B9*1000)*B11 -> 84417826 | C15: =(C9*1000)*C11 -> 117396000 | D15: =(D9*1000)*D11 -> 139960000 | E15: =(E9*1000)*E11 -> 87207500 | F15: =(F9*1000)*F11 -> 134502500 | G15: =(G9*1000)*G11 -> 119970000 | H15: =(H9*1000)*H11 -> 116256000 | I15: =(I9*1000)*I11 -> 1.2069e+08 | ... M15: =(M9*1000)*M11 -> 94410000 | N15: =SUM(B15:M15) -> 1358887326
A17: Co-products prices , THB/kg
A18: Pulp (moisture 79%) | B18: 0.282 | C18: 0.254 | D18: 0.254 | E18: 0.254 | F18: 0.254 | G18: 0.254 | H18: 0.254 | I18: 0.254 | J18: 0.254 | K18: 0.254 | L18: 0.254 | M18: 0.254 | N18: =AVERAGE(B18:M18) -> 0.25633333
A19: Soil Skin | B19: 0.03 | C19: 0.03 | D19: 0.03 | E19: 0.03 | F19: 0.03 | G19: 0.03 | H19: 0.03 | I19: 0.03 | J19: 0.03 | K19: 0.03 | L19: 0.03 | M19: 0.03 | N19: =AVERAGE(B19:M19) -> 0.03
A20: Wash Skin | B20: 0.2 | C20: 0.2 | D20: 0.2 | E20: 0.2 | F20: 0.2 | G20: 0.2 | H20: 0.2 | I20: 0.2 | J20: 0.2 | K20: 0.2 | L20: 0.2 | M20: 0.2 | N20: =AVERAGE(B20:M20) -> 0.2
A21: Pulp moisture, actual | B21: 0.7875
A24: KSN plant | B24: Jan | C24: Feb | D24: Mar | E24: Apr | F24: May | G24: Jun | H24: Jul | I24: Aug | J24: Sep | K24: Oct | L24: Nov | M24: Dec | N24: Total/Avg.
A26: Day operation | B26: 28 | C26: 28 | D26: 31 | E26: 24 | F26: 31 | G26: 30 | H26: 31 | I26: 31 | J26: 30 | K26: 31 | L26: 30 | M26: 26 | N26: =SUM(B26:M26) -> 351
A27: Grinding/day without waxy | B27: =B28/B26 -> 516.30804 | C27: 600 | D27: 650 | E27: 700 | F27: 700 | G27: 700 | H27: 700 | I27: 700 | J27: 700 | K27: 700 | L27: 700 | M27: 600 | N27: =N28/N26 -> 665.54594
A28: Grinding/month , tons | B28: 14456.625 | C28: =C27*C26 -> 16800 | D28: =D27*D26 -> 20150 | E28: =E27*E26 -> 16800 | F28: =F27*F26 -> 21700 | G28: =G27*G26 -> 21000 | H28: =H27*H26 -> 21700 | I28: =I27*I26 -> 21700 | J28: =J27*J26 -> 21000 | ... M28: =M27*M26 -> 15600 | N28: =SUM(B28:M28) -> 233606.62
A30: Roots purchased/month , tons | B30: 15610.621 | C30: 16800 | D30: 20150 | E30: 16800 | F30: 21700 | G30: 21000 | H30: 21700 | I30: 21700 | J30: 21000 | K30: 21700 | L30: 21000 | M30: 15600 | N30: =SUM(B30:M30) -> 234760.62
A31: Actual starch content | B31: 27.464032 | C31: 27.333333 | D31: ='[60]KSN MAP - Mar 2026 (2)'!G13 -> 26.184615 | E31: ='[60]KSN MAP - Apr 2026 (2)'!G13 -> 23.807143 | F31: ='[60]KSN MAP - May 2026 (2)'!G13 -> 21.551429 | G31: ='[60]KSN MAP - Jun 2026 (2)'!G13 -> 21.496429 | H31: ='[60]KSN MAP - Jul 2026 (2)'!G13 -> 21.995 | I31: ='[60]KSN MAP - Aug 2026 (2)'!G13 -> 23.5 | J31: ='[60]KSN MAP - Sep 2026 (2)'!G13 -> 24.404286 | K31: ='[60]KSN MAP - Oct 2026 (2)'!G13 -> 25.2 | L31: ='[60]KSN MAP - Nov 2026 (2)'!G13 -> 25.7 | M31: ='[60]KSN MAP - Dec 2026 (2)'!G13 -> 27.5 | N31: =N35/(N30*1000)*100 -> 24.492494
A32: Actual price | B32: 2.9210987 | C32: 2.9346667 | D32: ='[60]KSN MAP - Mar 2026 (2)'!H13 -> 2.8946154 | E32: ='[60]KSN MAP - Apr 2026 (2)'!H13 -> 2.8442857 | F32: ='[60]KSN MAP - May 2026 (2)'!H13 -> 2.7264286 | G32: ='[60]KSN MAP - Jun 2026 (2)'!H13 -> 2.755 | H32: ='[60]KSN MAP - Jul 2026 (2)'!H13 -> 2.7142857 | I32: ='[60]KSN MAP - Aug 2026 (2)'!H13 -> 2.7942857 | J32: ='[60]KSN MAP - Sep 2026 (2)'!H13 -> 2.8342857 | K32: ='[60]KSN MAP - Oct 2026 (2)'!H13 -> 2.9057143 | L32: ='[60]KSN MAP - Nov 2026 (2)'!H13 -> 2.9971429 | M32: ='[60]KSN MAP - Dec 2026 (2)'!H13 -> 3.0833333 | N32: =N36/(N30*1000) -> 2.859004 | R32: =R11 -> Actual 2025
A33: PPDS | B33: 10.636088 | C33: =C32/C31*100 -> 10.736585 | D33: =D32/D31*100 -> 11.054642 | E33: =E32/E31*100 -> 11.947195 | F33: =F32/F31*100 -> 12.650802 | G33: =G32/G31*100 -> 12.816082 | H33: =H32/H31*100 -> 12.340467 | I33: =I32/I31*100 -> 11.890578 | J33: =J32/J31*100 -> 11.613885 | ... N33: =N32/N31*100 -> 11.67298 | P33: =#REF! -> #REF! | R33: =#REF! -> #REF!
A35: Weight starch , kg | B35: =((B30*1000)*B31)/100 -> 4287306 | C35: =((C30*1000)*C31)/100 -> 4592000 | D35: =((D30*1000)*D31)/100 -> 5276200 | E35: =((E30*1000)*E31)/100 -> 3999600 | F35: =((F30*1000)*F31)/100 -> 4676660 | G35: =((G30*1000)*G31)/100 -> 4514250 | H35: =((H30*1000)*H31)/100 -> 4772915 | I35: =((I30*1000)*I31)/100 -> 5099500 | ... M35: =((M30*1000)*M31)/100 -> 4290000 | N35: =SUM(B35:M35) -> 57498731
A36: Amount , THB | B36: =(B30*1000)*B32 -> 45600164 | C36: =(C30*1000)*C32 -> 49302400 | D36: =(D30*1000)*D32 -> 58326500 | E36: =(E30*1000)*E32 -> 47784000 | F36: =(F30*1000)*F32 -> 59163500 | G36: =(G30*1000)*G32 -> 57855000 | H36: =(H30*1000)*H32 -> 58900000 | I36: =(I30*1000)*I32 -> 60636000 | ... M36: =(M30*1000)*M32 -> 48100000 | N36: =SUM(B36:M36) -> 6.7118156e+08
A38: Co-products prices, THB/kg
A39: Pulp | B39: 0.134 | C39: 0.134 | D39: 0.134 | E39: 0.134 | F39: 0.134 | G39: 0.134 | H39: 0.134 | I39: 0.134 | J39: 0.134 | K39: 0.134 | L39: 0.134 | M39: 0.134 | N39: =AVERAGE(B39:M39) -> 0.134
A40: Soil Skin | B40: 0.03 | C40: 0.03 | D40: 0.03 | E40: 0.03 | F40: 0.03 | G40: 0.03 | H40: 0.03 | I40: 0.03 | J40: 0.03 | K40: 0.03 | L40: 0.03 | M40: 0.03 | N40: =AVERAGE(B40:M40) -> 0.03
A41: Wash Skin | B41: 0.12 | C41: 0.12 | D41: 0.12 | E41: 0.12 | F41: 0.12 | G41: 0.12 | H41: 0.12 | I41: 0.12 | J41: 0.12 | K41: 0.12 | L41: 0.12 | M41: 0.12 | N41: =AVERAGE(B41:M41) -> 0.12

Sheet LV02.04.2026 cost_Origi
A1: 2026 Cost projection_LV:26/3/2026 | E1: Monthly
E2: LV:26/3/2026 | F2: LV:26/3/2026 | G2: LV:26/3/2026 | H2: LV:26/3/2026 | I2: LV:26/3/2026 | J2: LV:26/3/2026 | K2: LV:26/3/2026 | L2: LV:26/3/2026 | M2: LV:26/3/2026
A3: SK plant | B3: Jan | C3: Feb | D3: Mar | E3: Apr | F3: May | G3: Jun | H3: Jul | I3: Aug | J3: Sep | K3: Oct | L3: Nov | M3: Dec | N3: Total/Avg.
A5: Day operation | B5: 27 | C5: 28 | D5: 31 | E5: 24 | F5: 31 | G5: 30 | H5: 30 | I5: 31 | J5: 31 | K5: 31 | L5: 30 | M5: 26 | N5: =SUM(B5:M5) -> 350 | P5: Plan
A6: Grinding/day without waxy | B6: =B7/B5 -> 1088.8185 | C6: 1087.38 | D6: =D7/D5 -> 1082.5681 | E6: 1450 | F6: 1450 | G6: 1400 | H6: 1400 | I6: 1400 | J6: 1300 | K6: 1200 | L6: 1200 | M6: 1200 | N6: =N7/N5 -> 1186.2355 | P6: Apr-Dec
A7: Grinding/month , tons | B7: 29398.1 | C7: 30446.73 | D7: 33559.61 | E7: 26978 | F7: 39250 | G7: 39800 | H7: 41800 | I7: 41700 | J7: 37200 | K7: 34300 | L7: 33150 | M7: 27600 | N7: =SUM(B7:M7) -> 415182.44 | P7: From Planner
A9: Roots purchased/month , tons | B9: 29954.31 | C9: 30325.58 | D9: 33527.15 | E9: ='SK MAP - Apr 2026 _ 26.03.2026'!E6 -> 29500 | F9: ='SK MAP - May 2026 _ 26.03.2026'!E6 -> 39250 | G9: ='SK MAP -June 2026 _ 26.03.2026'!E6 -> 41050 | H9: ='SK MAP -July 2026 _ 26.03.26'!E6 -> 41800 | I9: ='SK MAP -Aug 2026 _ 26.03.26'!E6 -> 41700 | J9: ='SK MAP -Sep 2026 _ 26.03.26 '!E6 -> 37200 | K9: ='SK MAP -Oct 2026 _ 26.03.26'!E6 -> 34300 | L9: ='SK MAP -Nov 2026 _ 26.03.26'!E6 -> 33150 | M9: ='SK MAP -Dec 2026 _ 26.03.26 '!E6 -> 27600 | N9: =SUM(B9:M9) -> 419357.04
A10: Starch content , % | B10: 27.073368 | C10: 26.63 | D10: 24.644387 | E10: ='SK MAP - Apr 2026 _ 26.03.2026'!E7*100 -> 21.969492 | F10: ='SK MAP - May 2026 _ 26.03.2026'!E7*100 -> 20.970382 | G10: ='SK MAP -June 2026 _ 26.03.2026'!G13 -> 21 | H10: ='SK MAP -July 2026 _ 26.03.26'!E7*100 -> 22 | I10: ='SK MAP -Aug 2026 _ 26.03.26'!E7*100 -> 22.504484 | J10: ='SK MAP -Sep 2026 _ 26.03.26 '!E7*100 -> 22.801935 | K10: ='SK MAP -Oct 2026 _ 26.03.26'!E7*100 -> 22.995773 | L10: ='SK MAP -Nov 2026 _ 26.03.26'!E7*100 -> 24 | M10: ='SK MAP -Dec 2026 _ 26.03.26 '!E7*100 -> 25 | N10: =N14/(N9*1000)*100 -> 23.270203
A11: Price , THB/kg. | B11: 2.8182197 | C11: 2.92 | D11: 2.9583502 | E11: ='SK MAP - Apr 2026 _ 26.03.2026'!E8 -> 3.0755932 | F11: ='SK MAP - May 2026 _ 26.03.2026'!E8 -> 3.1263057 | G11: ='SK MAP -June 2026 _ 26.03.2026'!H13 -> 3.0808161 | H11: ='SK MAP -July 2026 _ 26.03.26'!E8 -> 3.1277512 | I11: ='SK MAP -Aug 2026 _ 26.03.26'!E8 -> 3.1165468 | J11: ='SK MAP -Sep 2026 _ 26.03.26 '!E8 -> 3.0435484 | K11: ='SK MAP -Oct 2026 _ 26.03.26'!E8 -> 2.955102 | L11: ='SK MAP -Nov 2026 _ 26.03.26'!E8 -> 3.0776018 | M11: ='SK MAP -Dec 2026 _ 26.03.26 '!E8 -> 3.1746377 | N11: =N15/(N9*1000) -> 3.0454125 | R11: Actual 2025
A12: PPDS , THB/kg. | B12: =B11/B10*100 -> 10.409564 | C12: 10.98 | D12: 12.004154 | E12: ='SK MAP - Apr 2026 _ 26.03.2026'!E9 -> 13.999383 | F12: ='SK MAP - May 2026 _ 26.03.2026'!E9 -> 14.908196 | G12: ='SK MAP -June 2026 _ 26.03.2026'!I13 -> 14.670553 | H12: ='SK MAP -July 2026 _ 26.03.26'!E9 -> 14.217051 | I12: ='SK MAP -Aug 2026 _ 26.03.26'!E9 -> 13.848559 | J12: ='SK MAP -Sep 2026 _ 26.03.26 '!E9 -> 13.347763 | K12: ='SK MAP -Oct 2026 _ 26.03.26'!E9 -> 12.850632 | L12: ='SK MAP -Nov 2026 _ 26.03.26'!E9 -> 12.823341 | M12: ='SK MAP -Dec 2026 _ 26.03.26 '!E9 -> 12.698551 | N12: =N11/N10*100 -> 13.087176 | P12: =#REF! -> #REF! | R12: =#REF! -> #REF!
A14: Weight starch , kg | B14: =((B9*1000)*B10)/100 -> 8109640.5 | C14: 8074417.2 | D14: =((D9*1000)*D10)/100 -> 8262560.5 | E14: =((E9*1000)*E10)/100 -> 6481000 | F14: =((F9*1000)*F10)/100 -> 8230875 | G14: =((G9*1000)*G10)/100 -> 8620500 | H14: =((H9*1000)*H10)/100 -> 9196000 | I14: =((I9*1000)*I10)/100 -> 9384370 | J14: =((J9*1000)*J10)/100 -> 8482320 | K14: =((K9*1000)*K10)/100 -> 7887550 | ... M14: =((M9*1000)*M10)/100 -> 6900000 | N14: =SUM(B14:M14) -> 97585233
A15: Amount , THB | B15: =(B9*1000)*B11 -> 84417826 | C15: 88684792 | D15: =(D9*1000)*D11 -> 99185052 | E15: =(E9*1000)*E11 -> 90730000 | F15: =(F9*1000)*F11 -> 122707500 | G15: =(G9*1000)*G11 -> 126467500 | H15: =(H9*1000)*H11 -> 1.3074e+08 | I15: =(I9*1000)*I11 -> 129960000 | J15: =(J9*1000)*J11 -> 113220000 | K15: =(K9*1000)*K11 -> 1.0136e+08 | ... M15: =(M9*1000)*M11 -> 87620000 | N15: =SUM(B15:M15) -> 1.2771152e+09
A17: Co-products prices , THB/kg
A18: Pulp (moisture 79%) | B18: 0.282 | C18: 0.282 | D18: 0.36561484 | E18: 0.254 | F18: 0.254 | G18: 0.254 | H18: 0.254 | I18: 0.254 | J18: 0.254 | K18: 0.254 | L18: 0.254 | M18: 0.254 | N18: =AVERAGE(B18:M18) -> 0.2679679
A19: Soil Skin | B19: 0.03 | C19: 0.03 | D19: 0.03 | E19: 0.03 | F19: 0.03 | G19: 0.03 | H19: 0.03 | I19: 0.03 | J19: 0.03 | K19: 0.03 | L19: 0.03 | M19: 0.03 | N19: =AVERAGE(B19:M19) -> 0.03
A20: Wash Skin | B20: 0.2 | C20: 0.2 | D20: 0.24733343 | E20: 0.2 | F20: 0.2 | G20: 0.2 | H20: 0.2 | I20: 0.2 | J20: 0.2 | K20: 0.2 | L20: 0.2 | M20: 0.2 | N20: =AVERAGE(B20:M20) -> 0.20394445
A21: Pulp moisture, actual | B21: 0.7875 | C21: 0.7869 | D21: 0.78003438
A23: 2026 Cost projection_LV:2/4/2026
E24: Monthly Rev.01 | F24: LV:2/4/2026 | G24: LV:2/4/2026 | H24: LV:2/4/2026 | I24: LV:2/4/2026 | J24: LV:2/4/2026 | K24: LV:2/4/2026 | L24: LV:2/4/2026 | M24: LV:2/4/2026
A25: KSN plant | B25: Jan | C25: Feb | D25: Mar | E25: Apr | F25: May | G25: Jun | H25: Jul | I25: Aug | J25: Sep | K25: Oct | L25: Nov | M25: Dec | N25: Total/Avg.
C26: Stop 1 day | D26: Stop 2 days
A27: Day operation | B27: 28 | C27: 27 | D27: 29 | E27: 24 | F27: 31 | G27: 30 | H27: 31 | I27: 31 | J27: 30 | K27: 31 | L27: 30 | M27: 26 | N27: =SUM(B27:M27) -> 348
A28: Grinding/day without waxy | B28: =B29/B27 -> 516.30804 | C28: 519.15 | D28: =D29/D27 -> 507.18548 | E28: 700 | F28: 700 | G28: 700 | H28: 700 | I28: 700 | J28: 700 | K28: 700 | L28: 700 | M28: 600 | N28: =N29/N27 -> 647.64921
A29: Grinding/month , tons | B29: 14456.625 | C29: 14016.92 | D29: 14708.379 | E29: =E28*E27 -> 16800 | F29: =F28*F27 -> 21700 | G29: =G28*G27 -> 21000 | H29: =H28*H27 -> 21700 | I29: =I28*I27 -> 21700 | J29: =J28*J27 -> 21000 | K29: =K28*K27 -> 21700 | L29: =L28*L27 -> 21000 | M29: =M28*M27 -> 15600 | N29: =SUM(B29:M29) -> 225381.92
A31: Roots purchased/month , tons | B31: 15610.621 | C31: 14627.14 | D31: 14093.328 | E31: ='KSN MAP - Apr 2026 (2)'!E6 -> 16800 | F31: 21700 | G31: 21000 | H31: 21700 | I31: 21700 | J31: 21000 | K31: 21700 | L31: 21000 | M31: 15600 | N31: =SUM(B31:M31) -> 226531.09
A32: Actual starch content | B32: 27.464032 | C32: 27.61 | D32: 25.43097 | E32: ='KSN MAP - Apr 2026 Rev1-2.04.26'!G13 -> 23 | F32: ='KSN MAP - May 2026_02.04.26'!G13 -> 21.551429 | G32: ='KSN MAP - Jun 2026_02.04.26'!G13 -> 21.496429 | H32: ='KSN MAP - Jul 2026_02.04.26'!G13 -> 21.995 | I32: ='KSN MAP - Aug 2026_02.04.26'!G13 -> 23.5 | J32: ='KSN MAP - Sep 2026 _02.04.26'!G13 -> 24.404286 | K32: ='KSN MAP - Oct 2026_02.04.26'!G13 -> 25.2 | L32: ='KSN MAP - Nov 2026 _02.04.26'!G13 -> 25.7 | M32: ='KSN MAP - Dec 2026 _02.04.26'!G13 -> 27.5 | N32: =N36/(N31*1000)*100 -> 24.330816
A33: Actual price | B33: 2.9210987 | C33: 2.95 | D33: 2.8933837 | E33: ='KSN MAP - Apr 2026 Rev1-2.04.26'!H13 -> 3.0985714 | F33: ='KSN MAP - May 2026_02.04.26'!H13 -> 3.005 | G33: ='KSN MAP - Jun 2026_02.04.26'!H13 -> 3.0014286 | H33: ='KSN MAP - Jul 2026_02.04.26'!H13 -> 2.9785714 | I33: ='KSN MAP - Aug 2026_02.04.26'!H13 -> 3.0085714 | J33: ='KSN MAP - Sep 2026 _02.04.26'!H13 -> 2.9985714 | K33: ='KSN MAP - Oct 2026_02.04.26'!H13 -> 3.0628571 | L33: ='KSN MAP - Nov 2026 _02.04.26'!H13 -> 3.1328571 | M33: ='KSN MAP - Dec 2026 _02.04.26'!H13 -> 3.2166667 | N33: =N37/(N31*1000) -> 3.0242394 | R33: =R11 -> Actual 2025
A34: PPDS | B34: 10.636088 | C34: 10.67 | D34: 11.377402 | E34: =E33/E32*100 -> 13.47205 | F34: =F33/F32*100 -> 13.943391 | G34: =G33/G32*100 -> 13.962452 | H34: =H33/H32*100 -> 13.542039 | I34: =I33/I32*100 -> 12.802432 | J34: =J33/J32*100 -> 12.287069 | K34: =K33/K32*100 -> 12.154195 | L34: =L33/L32*100 -> 12.190106 | ... N34: =N33/N32*100 -> 12.429667 | P34: =#REF! -> #REF! | R34: =#REF! -> #REF!
A36: Weight starch , kg | B36: =((B31*1000)*B32)/100 -> 4287306 | C36: 4037862 | D36: =((D31*1000)*D32)/100 -> 3584070 | E36: =((E31*1000)*E32)/100 -> 3864000 | F36: =((F31*1000)*F32)/100 -> 4676660 | G36: =((G31*1000)*G32)/100 -> 4514250 | H36: =((H31*1000)*H32)/100 -> 4772915 | I36: =((I31*1000)*I32)/100 -> 5099500 | J36: =((J31*1000)*J32)/100 -> 5124900 | K36: =((K31*1000)*K32)/100 -> 5468400 | ... M36: =((M31*1000)*M32)/100 -> 4290000 | N36: =SUM(B36:M36) -> 55116863
A37: Amount , THB | B37: =(B31*1000)*B33 -> 45600164 | C37: 43087170 | D37: =(D31*1000)*D33 -> 40777405 | E37: =(E31*1000)*E33 -> 52056000 | F37: =(F31*1000)*F33 -> 65208500 | G37: =(G31*1000)*G33 -> 63030000 | H37: =(H31*1000)*H33 -> 64635000 | I37: =(I31*1000)*I33 -> 65286000 | J37: =(J31*1000)*J33 -> 62970000 | K37: =(K31*1000)*K33 -> 66464000 | ... M37: =(M31*1000)*M33 -> 50180000 | N37: =SUM(B37:M37) -> 6.8508424e+08
A39: Co-products prices, THB/kg
A40: Pulp | B40: 0.134 | C40: 0.134 | D40: 0.134 | E40: 0.134 | F40: 0.134 | G40: 0.134 | H40: 0.134 | I40: 0.134 | J40: 0.134 | K40: 0.134 | L40: 0.134 | M40: 0.134 | N40: =AVERAGE(B40:M40) -> 0.134
A41: Soil Skin | B41: 0.03 | C41: 0.03 | D41: 0.03 | E41: 0.03 | F41: 0.03 | G41: 0.03 | H41: 0.03 | I41: 0.03 | J41: 0.03 | K41: 0.03 | L41: 0.03 | M41: 0.03 | N41: =AVERAGE(B41:M41) -> 0.03
A42: Wash Skin | B42: 0.12 | C42: 0.12 | D42: 0.12 | E42: 0.12 | F42: 0.12 | G42: 0.12 | H42: 0.12 | I42: 0.12 | J42: 0.12 | K42: 0.12 | L42: 0.12 | M42: 0.12 | N42: =AVERAGE(B42:M42) -> 0.12

Sheet SK ST+Price+PPDS+Farmer_Origi.
B2: SK plant
B4: Starch content in root (%)
B5: Month | C5: 2026 El Niño | D5: 2025 La Niña | E5: 2024 El Niño | F5: 2023 El Niño | G5: 2022 La Niña | H5: 2021 La Niña | I5: 2020 La Niña | J5: 2019 | K5: 2018 | L5: 2017 | M5: 2016 | N5: 2015
B6: Jan | C6: 27.073368 | D6: 27.465482 | E6: 26.552126 | F6: 28.283012 | G6: 28.075819 | H6: 28.283416 | I6: 26.452771 | J6: 27.600559 | K6: 28.75 | L6: 28.48 | M6: 27.988439 | N6: 28.53
B7: Feb | C7: ='LE02026 cost LV11022026_Origi'!C10 -> 27.256311 | D7: 27.142097 | E7: 27.098026 | F7: 28.246149 | G7: 27.665692 | H7: 28.343564 | I7: 26.436967 | J7: 27.6 | K7: 28.75 | L7: 28.99 | M7: 28.524987 | N7: 28.9513
B8: Mar | C8: ='LE02026 cost LV11022026_Origi'!D10 -> 25.742204 | D8: 25.506314 | E8: 25.153572 | F8: 27.27257 | G8: 26.223927 | H8: 26.636336 | I8: 24.42815 | J8: 25.985059 | K8: 26.75 | L8: 27.941922 | M8: 27.796808 | N8: 26.68091
B9: Apr | C9: =#REF! -> #REF! | D9: 22.363459 | E9: 21.636709 | F9: 24.331309 | G9: 24.772808 | H9: 24.116969 | I9: 21.491937 | J9: 22.72 | K9: 24.85 | L9: 25.393449 | M9: 25.197741 | N9: 25.48
B10: May | C10: =#REF! -> #REF! | D10: 19.449638 | E10: 18.241591 | F10: 20.530842 | G10: 23.098356 | H10: 22.594208 | I10: 20.447716 | J10: 20.44 | K10: 23.39 | L10: 23.453555 | M10: 22.082839 | N10: 24.298698
B11: Jun | C11: =#REF! -> #REF! | D11: 20.598081 | E11: 16.633931 | F11: 20.08 | G11: 23.058919 | H11: 22.643665 | I11: 20.831887 | J11: 21.06 | K11: 23.75 | L11: 24.251453 | M11: 20.984485 | N11: 22.924381
B12: Jul | C12: =#REF! -> #REF! | D12: 23.384067 | E12: 18.040337 | F12: 22.568159 | G12: 24.122682 | H12: 23.921738 | I12: 22.260539 | J12: 22.05 | K12: 24.95 | L12: 25.399363 | M12: 22.366981 | N12: 22.238087
B13: Aug | C13: =#REF! -> #REF! | D13: 24.238562 | E13: 21.33516 | F13: 24.498753 | G13: 24.589269 | H13: 24.39491 | I13: 23.375192 | J13: 22.9 | K13: 25.87 | L13: 25.874386 | M13: 25.135475 | N13: 23.603732
B14: Sep | C14: =#REF! -> #REF! | D14: 24.537915 | E14: 23.015575 | F14: 24.04 | G14: 25.249353 | H14: 24.676516 | I14: 23.848565 | J14: 23.22 | K14: 26.47 | L14: 25.921535 | M14: 25.698979 | N14: 23.984547
B15: Oct | C15: =#REF! -> #REF! | D15: 24.001491 | E15: 23.447747 | F15: 23.844147 | G15: 25.791357 | H15: 24.768643 | I15: 24.304353 | J15: 24.51 | K15: 26.07 | L15: 25.911833 | M15: 25.764254 | N15: 24.596381
B16: Nov | C16: =#REF! -> #REF! | D16: 24.842139 | E16: 24.281086 | F16: 24.370364 | G16: 27.209794 | H16: 25.410465 | I16: 25.208214 | J16: 25.28 | K16: 26.428 | L16: 26.88 | M16: 25.574764 | N16: 25.327068
B17: Dec | C17: =#REF! -> #REF! | D17: 25.807675 | E17: 25.663568 | F17: 25.544211 | G17: 27.303537 | H17: 27.091963 | I17: 27.464238 | J17: 25.97 | K17: 27.402526 | L17: 28.2 | M17: 27.132339 | N17: 26.911576
B18: YTD | C18: =#REF! -> #REF! | D18: 23.891104 | E18: 22.277682 | F18: 24.550107 | G18: 25.463697 | H18: 25.035661 | I18: 23.766044 | J18: 23.968278 | K18: 26.167983 | L18: 26.324424 | M18: 25.23 | N18: 25.08
D19: =C9-E19 -> #REF! | E19: =D9-D10 -> 2.9138212
E20: Apr-May : El Niño Jun-Aug : La Niña | F20: Drought | G20: Continue rain | H20: Flooding | I20: Co-vid19 | J20: Drought/CMD | K20: Crisis /Drought /CMD | L20: Senka - Flooding | M20: Drought
B21: Price (THB./Kg.)
B22: Month | C22: 2026 | D22: 2025 | E22: 2024 | F22: 2023 | G22: 2022 | H22: 2021 | I22: 2020 | J22: 2019 | K22: 2018 | L22: 2017 | M22: 2016 | N22: 2015
B23: Jan | C23: 2.8182197 | D23: 2.3206125 | E23: 3.8811187 | F23: 3.3707016 | G23: 2.8679964 | H23: 2.4321249 | I23: 2.4349758 | J23: 2.7330793 | K23: 2.6846275 | L23: 1.9640519 | M23: 2.3831074 | N23: 2.6862319
B24: Feb | C24: ='LE02026 cost LV11022026_Origi'!C11 -> 2.8494175 | D24: 2.2929551 | E24: 3.8121126 | F24: 3.5307178 | G24: 2.8003392 | H24: 2.5347841 | I24: 2.3773005 | J24: 2.6221188 | K24: 2.7929828 | L24: 1.9008149 | M24: 2.2986145 | N24: 2.5758909
B25: Mar | C25: ='LE02026 cost LV11022026_Origi'!D11 -> 2.9097713 | D25: 2.0350253 | E25: 3.52454 | F25: 3.8271873 | G25: 2.9025373 | H25: 2.4968198 | I25: 2.2580928 | J25: 2.6008877 | K25: 3.0816588 | L25: 1.8959876 | M25: 2.2863871 | N25: 2.412576
B26: Apr | C26: =#REF! -> #REF! | D26: 1.8683628 | E26: 3.1336716 | F26: 3.9203079 | G26: 3.0721751 | H26: 2.5831193 | I26: 2.0728862 | J26: 2.4824865 | K26: 3.4087085 | L26: 1.7969313 | M26: 2.3015141 | N26: 2.4720834
B27: May | C27: =#REF! -> #REF! | D27: 1.8105822 | E27: 2.8330475 | F27: 3.591888 | G27: 3.2212402 | H27: 2.4395852 | I27: 2.1191505 | J27: 2.2385166 | K27: 3.2121688 | L27: 1.7619482 | M27: 2.1283473 | N27: 2.4768338
B28: Jun | C28: =#REF! -> #REF! | D28: 1.9014496 | E28: 2.3804216 | F28: 3.1777245 | G28: 3.1931162 | H28: 2.4319136 | I28: 2.1076855 | J28: 2.1460582 | K28: 3.0607744 | L28: 1.7574709 | M28: 2.0202376 | N28: 2.5179536
B29: Jul | C29: =#REF! -> #REF! | D29: 2.3831165 | E29: 2.5238319 | F29: 3.4243199 | G29: 3.3706548 | H29: 2.5888143 | I29: 2.2176649 | J29: 2.302884 | K29: 3.0627285 | L29: 1.8329102 | M29: 1.9109423 | N29: 2.5808822
B30: Aug | C30: =#REF! -> #REF! | D30: 2.4913376 | E30: 2.7262263 | F30: 3.621204 | G30: 3.2971745 | H30: 2.6210172 | I30: 2.308271 | J30: 2.3741792 | K30: 3.0904943 | L30: 1.874876 | M30: 1.8615915 | N30: 2.5745389
B31: Sep | C31: =#REF! -> #REF! | D31: 2.4337319 | E31: 2.8448843 | F31: 3.5944677 | G31: 3.3406941 | H31: 2.7038312 | I31: 2.3222267 | J31: 2.3502101 | K31: 3.2067345 | L31: 2.0527029 | M31: 1.7232699 | N31: 2.5489264
B32: Oct | C32: =#REF! -> #REF! | D32: 2.3955283 | E32: 2.5731024 | F32: 3.543168 | G32: 3.2375012 | H32: 2.6903687 | I32: 2.325409 | J32: 2.3754588 | K32: 3.1382285 | L32: 2.2131489 | M32: 1.6437255 | N32: 2.4681459
B33: Nov | C33: =#REF! -> #REF! | D33: 2.5972745 | E33: 2.5105695 | F33: 3.8483627 | G33: 3.2710718 | H33: 2.8612413 | I33: 2.3976659 | J33: 2.4911511 | K33: 3.0520859 | L33: 2.4194326 | M33: 1.8990576 | N33: 2.5117689
B34: Dec | C34: =#REF! -> #REF! | D34: 2.6599125 | E34: 2.3272461 | F34: 3.8269274 | G34: 3.2197843 | H34: 2.8350489 | I34: 2.4806185 | J34: 2.4320356 | K34: 2.9205169 | L34: 2.5506959 | M34: 2.0687513 | N34: 2.440626
B35: YTD | C35: =#REF! -> #REF! | D35: 2.2460448 | E35: 2.8880699 | F35: 3.6135815 | G35: 3.1609713 | H35: 2.5957875 | I35: 2.280929 | J35: 2.4192097 | K35: 3.0572651 | L35: 1.9961105 | M35: 2.0306835 | N35: 2.5222972
B38: PPDS (THB./Kg.)
B39: Month | C39: 2026 | D39: 2025 | E39: 2024 | F39: 2023 | G39: 2022 | H39: 2021 | I39: 2020 | J39: 2019 | K39: 2018 | L39: 2017 | M39: 2016 | N39: 2015
B40: Jan | C40: 10.41 | D40: 8.4491964 | E40: 14.616979 | F40: 11.91776 | G40: 10.215184 | H40: 8.5991199 | I40: 9.187 | J40: 9.9022604 | K40: 9.3393593 | L40: 6.8955851 | M40: 8.5146134 | N40: 9.413831
B41: Feb | C41: ='LE02026 cost LV11022026_Origi'!C12 -> 10.454157 | D41: 8.4479659 | E41: 14.067861 | F41: 12.49982 | G41: 10.122065 | H41: 8.9430675 | I41: 8.9923347 | J41: 9.5019659 | K41: 9.716073 | L41: 6.5577669 | M41: 8.058249 | N41: 8.897324
B42: Mar | C42: ='LE02026 cost LV11022026_Origi'!D12 -> 11.303505 | D42: 7.9785161 | E42: 14.012085 | F42: 14.033101 | G42: 11.068279 | H42: 9.3737357 | I42: 9.2438142 | J42: 10.009166 | K42: 11.519522 | L42: 6.7854588 | M42: 8.2253586 | N42: 9.04233
B43: Apr | C43: =#REF! -> #REF! | D43: 8.354534 | E43: 14.483125 | F43: 16.112195 | G43: 12.4014 | H43: 10.710796 | I43: 9.6449485 | J43: 10.926437 | K43: 13.714599 | L43: 7.076358 | M43: 9.1338112 | N43: 9.7023998
B44: May | C44: =#REF! -> #REF! | D44: 9.3090793 | E44: 15.530704 | F44: 17.495084 | G44: 13.945756 | H44: 10.797392 | I44: 10.363752 | J44: 10.953312 | K44: 13.735717 | L44: 7.5124997 | M44: 9.6380148 | N44: 10.193278
...

Sheet KSN ST+Price+PPDS+Farmer_Origi
B2: KSN plant
B4: Starch content in root (%)
B5: Month | C5: 2026 El Niño | D5: 2025 La Niña | E5: 2024 El Niño | F5: 2023 El Niño | G5: 2022 La Niña | H5: 2021 La Niña | I5: 2020 La Niña | J5: 2019 | K5: 2018 | L5: 2017 | M5: 2016 | N5: 2015
B6: Jan | C6: 27.464032 | D6: 27.998711 | E6: 27.831058 | F6: 28.890165 | G6: 29.79685 | H6: 29.951744 | I6: 27.983759 | J6: 28.3263 | K6: 29.360267 | L6: 28.66 | M6: 28.58 | N6: 29.96
B7: Feb | C7: ='LE02026 cost LV11022026_Origi'!C31 -> 27.333333 | D7: 28.332372 | E7: 27.763914 | F7: 28.97 | G7: 28.897075 | H7: 29.888329 | I7: 28.328713 | J7: 27.99 | K7: 29.135215 | L7: 29 | M7: 29.1 | N7: 29.91
B8: Mar | C8: ='LE02026 cost LV11022026_Origi'!D31 -> 26.184615 | D8: 26.571255 | E8: 25.857648 | F8: 27.471619 | G8: 27.259585 | H8: 27.528401 | I8: 26.064775 | J8: 26.122664 | K8: 27.29331 | L8: 27.49 | M8: 28.3 | N8: 27.351603
B9: Apr | C9: =#REF! -> #REF! | D9: 23.546041 | E9: 23.014333 | F9: 23.549197 | G9: 25.455601 | H9: 24.752392 | I9: 22.982705 | J9: 23.57 | K9: 25.585359 | L9: 25.4 | M9: 25.24 | N9: 25.819486
B10: May | C10: =#REF! -> #REF! | D10: 20.654164 | E10: 18.614028 | F10: 20.110915 | G10: 22.712972 | H10: 21.841452 | I10: 21.197042 | J10: 20.38 | K10: 24.154912 | L10: 23.99 | M10: 21.2 | N10: 23.81
B11: Jun | C11: =#REF! -> #REF! | D11: 20.603923 | E11: 17.547046 | F11: 18.828485 | G11: 23.336883 | H11: 21.901615 | I11: 19.767931 | J11: 21.13 | K11: 24.529697 | L11: 24.8 | M11: 20.1 | N11: 23.136897
B12: Jul | C12: =#REF! -> #REF! | D12: 22.594806 | E12: 20.086249 | F12: 22.09855 | G12: 23.962162 | H12: 24.132313 | I12: 21.613157 | J12: 23.39 | K12: 24.902171 | L12: 25.36 | M12: 22.84 | N12: 23.048973
B13: Aug | C13: =#REF! -> #REF! | D13: 24.402037 | E13: 22.971605 | F13: 23.521527 | G13: 24.758563 | H13: 25.202569 | I13: 23.497326 | J13: 24.4 | K13: 25.398905 | L13: 25.32 | M13: 25.21 | N13: 24.14
B14: Sep | C14: =#REF! -> #REF! | D14: 24.325976 | E14: 24.393695 | F14: 23.500475 | G14: 25.502384 | H14: 24.637115 | I14: 24.475376 | J14: 24.18 | K14: 26.36366 | L14: 26 | M14: 26.02 | N14: 25.32228
B15: Oct | C15: =#REF! -> #REF! | D15: 24.318543 | E15: 24.929827 | F15: 22.977083 | G15: 25.838381 | H15: 25.089759 | I15: 24.952312 | J15: 25.16 | K15: 26.606374 | L15: 25.81 | M15: 26.95 | N15: 25.61
B16: Nov | C16: =#REF! -> #REF! | D16: 25.291087 | E16: 24.474989 | F16: 24.13544 | G16: 27.695088 | H16: 26.639214 | I16: 26.123322 | J16: 26.13 | K16: 27.142752 | L16: 27.15 | M16: 27.48 | N16: 26.57
B17: Dec | C17: =#REF! -> #REF! | D17: 26.88498 | E17: 26.427034 | F17: 26.922452 | G17: 28.171766 | H17: 28.718051 | I17: 28.293256 | J17: 27.34 | K17: 27.941427 | L17: 28.85 | M17: 28.39 | N17: 28.07
B18: YTD | C18: =#REF! -> #REF! | D18: 24.261657 | E18: 23.134132 | F18: 24.01466 | G18: 25.909621 | H18: 25.501995 | I18: 24.233087 | J18: 24.603335 | K18: 26.408333 | L18: 26.389148 | M18: 25.44 | N18: 25.82
E20: Apr-May : El Niño Jun-Aug : La Niña | F20: Drought | G20: Continue rain | H20: Flooding | I20: Co-vid19 | J20: Drought/CMD | K20: Crisis /Drought /CMD | L20: Senka - Flooding | M20: Drought
B21: Price (THB./Kg.)
B22: Month | C22: 2026 | D22: 2025 | E22: 2024 | F22: 2023 | G22: 2022 | H22: 2021 | I22: 2020 | J22: 2019 | K22: 2018 | L22: 2017 | M22: 2016 | N22: 2015
B23: Jan | C23: 2.9210987 | D23: 2.5153376 | E23: 3.9841768 | F23: 3.2305394 | G23: 2.8289854 | H23: 2.3969436 | I23: 2.512711 | J23: 2.7280059 | K23: 2.696913 | L23: 1.7575173 | M23: 2.3450617 | N23: 2.6225755
B24: Feb | C24: ='LE02026 cost LV11022026_Origi'!C32 -> 2.9346667 | D24: 2.4836266 | E24: 3.9021217 | F24: 3.3178 | G24: 2.7485421 | H24: 2.3849143 | I24: 2.4262581 | J24: 2.6591785 | K24: 2.7929384 | L24: 1.7066414 | M24: 2.2563447 | N24: 2.4865813
B25: Mar | C25: ='LE02026 cost LV11022026_Origi'!D32 -> 2.8946154 | D25: 2.0868943 | E25: 3.7081954 | F25: 3.7138849 | G25: 2.7082811 | H25: 2.329964 | I25: 2.2763665 | J25: 2.5430463 | K25: 2.9580896 | L25: 1.616567 | M25: 2.2148608 | N25: 2.3369921
B26: Apr | C26: =#REF! -> #REF! | D26: 1.9090338 | E26: 3.1475714 | F26: 3.7531813 | G26: 2.9025793 | H26: 2.4755762 | I26: 2.0372725 | J26: 2.4857329 | K26: 3.2826207 | L26: 1.4814408 | M26: 2.1353644 | N26: 2.4051347
B27: May | C27: =#REF! -> #REF! | D27: 1.7086305 | E27: 2.5878252 | F27: 3.1862869 | G27: 2.831493 | H27: 2.2663244 | I27: 2.0589458 | J27: 2.0472088 | K27: 3.0082832 | L27: 1.4697588 | M27: 1.8874036 | N27: 2.2677044
B28: Jun | C28: =#REF! -> #REF! | D28: 1.7616423 | E28: 2.1395366 | F28: 2.7686582 | G28: 2.8998355 | H28: 2.099712 | I28: 1.9367071 | J28: 1.9603276 | K28: 2.7831103 | L28: 1.4530547 | M28: 1.7727738 | N28: 2.3333356
B29: Jul | C29: =#REF! -> #REF! | D29: 1.9924686 | E29: 2.2800426 | F29: 2.9913696 | G29: 2.9728337 | H29: 2.2225414 | I29: 2.0233899 | J29: 2.0328453 | K29: 2.7763127 | L29: 1.5712545 | M29: 1.7685839 | N29: 2.3649371
B30: Aug | C30: =#REF! -> #REF! | D30: 2.10573 | E30: 2.2553393 | F30: 2.9003964 | G30: 2.9757138 | H30: 2.2592082 | I30: 2.0236813 | J30: 2.0770868 | K30: 2.6944052 | L30: 1.5526732 | M30: 1.6862067 | N30: 2.2677514
B31: Sep | C31: =#REF! -> #REF! | D31: 2.1321625 | E31: 2.4102102 | F31: 3.069449 | G31: 3.060559 | H31: 2.4908174 | I31: 1.9738633 | J31: 1.9726167 | K31: 2.9078292 | L31: 1.8559301 | M31: 1.5321458 | N31: 2.2959791
B32: Oct | C32: =#REF! -> #REF! | D32: 2.271931 | E32: 2.3921655 | F32: 3.2552228 | G32: 3.0786552 | H32: 2.565396 | I32: 2.132983 | J32: 2.2519283 | K32: 3.0302824 | L32: 2.0837522 | M32: 1.3423228 | N32: 2.3608616
B33: Nov | C33: =#REF! -> #REF! | D33: 2.6044364 | E33: 2.7203163 | F33: 3.8225022 | G33: 3.2549139 | H33: 2.8182062 | I33: 2.3789096 | J33: 2.5578976 | K33: 3.1416663 | L33: 2.4760928 | M33: 1.7800996 | N33: 2.5234369
B34: Dec | C34: =#REF! -> #REF! | D34: 2.271931 | E34: 2.5166382 | F34: 3.9160598 | G34: 3.160716 | H34: 2.7679215 | I34: 2.4757573 | J34: 2.5024061 | K34: 2.8384839 | L34: 2.6095655 | M34: 1.7629543 | N34: 2.4857577
B35: YTD | C35: =#REF! -> #REF! | D35: 2.1560263 | E35: 2.7456244 | F35: 3.3078485 | G35: 2.9542224 | H35: 2.4156792 | I35: 2.1673515 | J35: 2.2988835 | K35: 2.9087505 | L35: 1.8047401 | M35: 1.8609758 | N35: 2.3840134
B38: PPDS (THB./Kg.)
B39: Month | C39: 2026 | D39: 2025 | E39: 2024 | F39: 2023 | G39: 2022 | H39: 2021 | I39: 2020 | J39: 2019 | K39: 2018 | L39: 2017 | M39: 2016 | N39: 2015
B40: Jan | C40: 10.636088 | D40: 8.9837623 | E40: 14.315578 | F40: 11.182142 | G40: 9.4942433 | H40: 8.0026845 | I40: 8.97 | J40: 9.630647 | K40: 9.1855873 | L40: 6.1318817 | M40: 8.2055733 | N40: 8.7545334
B41: Feb | C41: ='LE02026 cost LV11022026_Origi'!C33 -> 10.736585 | D41: 8.7660383 | E41: 14.054653 | F41: 11.452537 | G41: 9.5114891 | H41: 7.9794168 | I41: 8.5646605 | J41: 9.5009204 | K41: 9.5861258 | L41: 5.8854481 | M41: 7.7531671 | N41: 8.3136127
B42: Mar | C42: ='LE02026 cost LV11022026_Origi'!D33 -> 11.054642 | D42: 7.8539546 | E42: 14.340807 | F42: 13.518988 | G42: 9.9351516 | H42: 8.4638552 | I42: 8.7334975 | J42: 9.7350193 | K42: 10.838149 | L42: 5.8794964 | M42: 7.8255764 | N42: 8.5442599
B43: Apr | C43: =#REF! -> #REF! | D43: 8.1076634 | E43: 13.67657 | F43: 15.937619 | G43: 11.402517 | H43: 10.001362 | I43: 8.8643722 | J43: 10.547872 | K43: 12.830075 | L43: 5.8329211 | M43: 8.4601465 | N43: 9.3151919
B44: May | C44: =#REF! -> #REF! | D44: 8.2725715 | E44: 13.902553 | F44: 15.84357 | G44: 12.466413 | H44: 10.376254 | I44: 9.7133636 | J44: 10.045914 | K44: 12.454126 | L44: 6.125333 | M44: 8.9015293 | N44: 9.5257509
B45: Jun | C45: =#REF! -> #REF! | D45: 8.5500334 | E45: 12.193144 | F45: 14.704626 | G45: 12.425976 | H45: 9.587019 | I45: 9.7972168 | J45: 9.2765628 | K45: 11.345881 | L45: 5.8586964 | M45: 8.8202944 | N45: 10.084911
...

Sheet Planner 1.4.2026
B2: Day operation | E2: 27 | F2: 28 | G2: 31 | H2: 24 | I2: 31 | J2: 30 | K2: 30 | L2: 31 | M2: 31 | N2: 31 | O2: 30 | P2: 26
B3: Average Regular Root Grinding/day in period no Grind Waxy | E3: 1340 | F3: 1200 | G3: 1210 | H3: 1450 | I3: 1450 | J3: 1400 | K3: 1400 | L3: 1400 | M3: 1300 | N3: 1200 | O3: 1200 | P3: 1200
E4: Actual | F4: Actual | G4: Actual | H4: Actual+Plan | I4: Plan | J4: Plan | K4: Plan | L4: Plan | M4: Plan | N4: Plan | O4: Plan | P4: Plan
B5: Quarter | E5: Q1 | H5: Q2 | K5: Q3 | N5: Q4
B6: Month | D6: UOM | E6: Jan | F6: Feb | G6: Mar | H6: Apr | I6: May | J6: Jun | K6: Jul | L6: Aug | M6: Sep | N6: Oct | O6: Nov | P6: Dec | Q6: TOTAL | S6: LE0 2026 | T6: 2.2026 | U6: 03.2026 vs LE0 2026 | V6: 03.2026 vs 2.2026
B7: Regular Root Grinding Volume | D7: MT | E7: =[62]Daily!AH16 -> 29398 | F7: =[62]Daily!BK16 -> 30446.73 | G7: =[62]Daily!CQ16 -> 33527 | H7: =[62]Daily!DV16 -> 26978 | I7: =[62]Daily!FB16 -> 39250 | J7: =[62]Daily!GG16 -> 39800 | K7: =[62]Daily!HM16 -> 41800 | L7: =[62]Daily!IS16 -> 41700 | M7: =[62]Daily!JX16 -> 37200 | N7: =[62]Daily!LD16 -> 34300 | O7: =[62]Daily!MI16 -> 33150 | P7: =[62]Daily!NO16 -> 27600 | Q7: =SUM(E7:P7) -> 415149.73 | S7: 445200 | T7: 411365.73 | U7: =Q7-S7 -> -30050.27 | V7: =Q7-T7 -> 3784
B8: Average Regular Root Grinding | D8: MT | E8: =[62]Daily!AH21 -> 1088.8148 | F8: =[62]Daily!BK21 -> 1087.3832 | G8: =[62]Daily!CQ21 -> 1081.5161 | H8: =[62]Daily!DV21 -> 1124.0833 | I8: =[62]Daily!FB21 -> 1266.129 | J8: =[62]Daily!GG21 -> 1326.6667 | K8: =[62]Daily!HM21 -> 1348.3871 | L8: =[62]Daily!IS21 -> 1345.1613 | M8: =[62]Daily!JX21 -> 1240 | N8: =[62]Daily!LD21 -> 1106.4516 | O8: =[62]Daily!MI21 -> 1105 | P8: =[62]Daily!NO21 -> 1061.5385 | Q8: =AVERAGE(E8:P8) -> 1181.761 | S8: 1271.0071 | T8: 1172.4798 | U8: =Q8-S8 -> -89.246131 | V8: =Q8-T8 -> 9.281138
B9: Regular PPDS | D9: THB/kg | E9: =[62]Daily!AH20 -> 10.41 | F9: =[62]Daily!BK20 -> 10.98 | G9: =[62]Daily!CQ20 -> 12 | H9: =[62]Daily!DV20 -> 14 | I9: =[62]Daily!FB20 -> 13.8 | J9: =[62]Daily!GG20 -> 12.166667 | K9: =[62]Daily!HM20 -> 12.94 | L9: =[62]Daily!IS20 -> 12.6 | M9: =[62]Daily!JX20 -> 12.3 | N9: =[62]Daily!LD20 -> 11.95 | O9: =[62]Daily!MI20 -> 11.73 | P9: =[62]Daily!NO20 -> 11.54 | U9: =Q9-S9 -> 0 | V9: =Q9-T9 -> 0
B10: Waxy Root Grinding Volume | D10: MT | E10: =[62]Daily!AH24 -> 2720 | F10: =[62]Daily!BK24 -> 2729 | G10: =[62]Daily!CQ24 -> 2114 | H10: =[62]Daily!DV24 -> 4000 | I10: =[62]Daily!FB24 -> 6528 | J10: =[62]Daily!GG24 -> 1225 | K10: =[62]Daily!HM24 -> 900 | L10: =[62]Daily!IS24 -> 900 | M10: =[62]Daily!JX24 -> 1500 | N10: =[62]Daily!LD24 -> 3000 | O10: =[62]Daily!MI24 -> 3000 | P10: =[62]Daily!NO24 -> 3000 | Q10: =SUM(E10:P10) -> 31616 | S10: 23876 | T10: 31502 | U10: =Q10-S10 -> 7740 | V10: =Q10-T10 -> 114
B11: GLUCOSE - Sales | D11: MT | E11: =[62]Daily!AH99 -> 5234 | F11: =[62]Daily!BK99 -> 5504 | G11: =[62]Daily!CQ99 -> 5620 | H11: =[62]Daily!DV99 -> 4154 | I11: =[62]Daily!FB99 -> 4367 | J11: =[62]Daily!GG99 -> 6202 | K11: =[62]Daily!HM99 -> 5756 | L11: =[62]Daily!IS99 -> 5505 | M11: =[62]Daily!JX99 -> 5587 | N11: =[62]Daily!LD99 -> 5699 | O11: =[62]Daily!MI99 -> 5405 | P11: =[62]Daily!NO99 -> 5250 | Q11: =SUM(E11:P11) -> 64283 | S11: 66285.5 | T11: 63615 | U11: =Q11-S11 -> -2002.5 | V11: =Q11-T11 -> 668
B12: HMS - Sales | D12: MT | E12: =[62]Daily!AH108 -> 570 | F12: =[62]Daily!BK108 -> 600 | G12: =[62]Daily!CQ108 -> 870 | H12: =[62]Daily!DV108 -> 650 | I12: =[62]Daily!FB108 -> 596 | J12: =[62]Daily!GG108 -> 499 | K12: =[62]Daily!HM108 -> 504 | L12: =[62]Daily!IS108 -> 503 | M12: =[62]Daily!JX108 -> 559 | N12: =[62]Daily!LD108 -> 708 | O12: =[62]Daily!MI108 -> 799 | P12: =[62]Daily!NO108 -> 804 | Q12: =SUM(E12:P12) -> 7662 | S12: 8220.3 | T12: 7891 | U12: =Q12-S12 -> -558.3 | V12: =Q12-T12 -> -229
B13: Total Glucose & HMS - Sales | D13: MT | E13: =E11+E12 -> 5804 | F13: =F11+F12 -> 6104 | G13: =G11+G12 -> 6490 | H13: =H11+H12 -> 4804 | I13: =I11+I12 -> 4963 | J13: =J11+J12 -> 6701 | K13: =K11+K12 -> 6260 | L13: =L11+L12 -> 6008 | ... P13: =P11+P12 -> 6054 | Q13: =SUM(E13:P13) -> 71945 | S13: 74505.8 | T13: 71506 | U13: =Q13-S13 -> -2560.8 | V13: =Q13-T13 -> 439
B14: Stock Glucose Ending | D14: MT | E14: =[62]Daily!AH114 -> 973 | F14: =[62]Daily!BK114 -> 856 | G14: =[62]Daily!CQ114 -> 713 | H14: =[62]Daily!DV114 -> 829 | I14: =[62]Daily!FB114 -> 966 | J14: =[62]Daily!GG114 -> 965 | K14: =[62]Daily!HM114 -> 1105 | L14: =[62]Daily!IS114 -> 1097 | M14: =[62]Daily!JX114 -> 1051 | N14: =[62]Daily!LD114 -> 944 | O14: =[62]Daily!MI114 -> 1040 | P14: =[62]Daily!NO114 -> 1286 | U14: =Q14-S14 -> 0 | V14: =Q14-T14 -> 0
B15: REGULAR STARCH - Production | D15: MT | E15: =[62]Daily!AH146 -> 2523.9 | F15: =[62]Daily!BK146 -> 2550.37 | G15: =[62]Daily!CQ146 -> 2647 | H15: =[62]Daily!DV146 -> 1885 | I15: =[62]Daily!FB146 -> 2859.8969 | J15: =[62]Daily!GG146 -> 1706.8321 | K15: =[62]Daily!HM146 -> 2539.0427 | L15: =[62]Daily!IS146 -> 3537.599 | M15: =[62]Daily!JX146 -> 2850.6087 | N15: =[62]Daily!LD146 -> 2276.5969 | O15: =[62]Daily!MI146 -> 2418.0644 | P15: =[62]Daily!NO146 -> 958.11872 | Q15: =SUM(E15:P15) -> 28753.03 | S15: 33406.027 | T15: 27390.397 | U15: =Q15-S15 -> -4652.9974 | V15: =Q15-T15 -> 1362.6325
B16: REGULAR STARCH - in-house total Sales | D16: MT | E16: =[62]Daily!AH157 -> 2029.13 | F16: =[62]Daily!BK157 -> 4453.24 | G16: =[62]Daily!CQ157 -> 2012 | H16: =[62]Daily!DV157 -> 2280 | I16: =[62]Daily!FB157 -> 4733 | J16: =[62]Daily!GG157 -> 2767 | K16: =[62]Daily!HM157 -> 2315 | L16: =[62]Daily!IS157 -> 3002 | M16: =[62]Daily!JX157 -> 2536 | N16: =[62]Daily!LD157 -> 2007 | O16: =[62]Daily!MI157 -> 2240 | P16: =[62]Daily!NO157 -> 1742 | Q16: =SUM(E16:P16) -> 32116.37 | S16: 36370.34 | T16: 30146.98 | U16: =Q16-S16 -> -4253.97 | V16: =Q16-T16 -> 1969.39
B17: REGULAR STARCH - 3P Export Sales | D17: MT | E17: =[62]Daily!AH152 -> 1094 | F17: =[62]Daily!BK152 -> 1940 | G17: =[62]Daily!CQ152 -> 537 | H17: =[62]Daily!DV152 -> 716 | I17: =[62]Daily!FB152 -> 2233 | J17: =[62]Daily!GG152 -> 1602 | K17: =[62]Daily!HM152 -> 596 | L17: =[62]Daily!IS152 -> 520 | M17: =[62]Daily!JX152 -> 579 | N17: =[62]Daily!LD152 -> 581 | O17: =[62]Daily!MI152 -> 500 | P17: =[62]Daily!NO152 -> 543 | Q17: =SUM(E17:P17) -> 11441 | S17: 15676.8 | T17: 10390 | U17: =Q17-S17 -> -4235.8 | V17: =Q17-T17 -> 1051
B18: REGULAR STARCH - 3P Domestic Sales | D18: MT | E18: =[62]Daily!AH153 -> 189 | F18: =[62]Daily!BK153 -> 200 | G18: =[62]Daily!CQ153 -> 272 | H18: =[62]Daily!DV153 -> 185 | I18: =[62]Daily!FB153 -> 216 | J18: =[62]Daily!GG153 -> 195 | K18: =[62]Daily!HM153 -> 172 | L18: =[62]Daily!IS153 -> 172 | M18: =[62]Daily!JX153 -> 175 | N18: =[62]Daily!LD153 -> 206 | O18: =[62]Daily!MI153 -> 217 | P18: =[62]Daily!NO153 -> 200 | Q18: =SUM(E18:P18) -> 2399 | S18: 2431.58 | T18: 2355 | U18: =Q18-S18 -> -32.58 | V18: =Q18-T18 -> 44
B19: REGULAR STARCH - Sales Network Optimize | D19: MT | E19: =[62]Daily!AH154 -> 0 | F19: =[62]Daily!BK154 -> 0 | G19: =[62]Daily!CQ154 -> 0 | H19: =[62]Daily!DV154 -> 0 | I19: =[62]Daily!FB154 -> 0 | J19: =[62]Daily!GG154 -> 0 | K19: =[62]Daily!HM154 -> 250 | L19: =[62]Daily!IS154 -> 270 | M19: =[62]Daily!JX154 -> 250 | N19: =[62]Daily!LD154 -> 250 | O19: =[62]Daily!MI154 -> 300 | P19: =[62]Daily!NO154 -> 250 | Q19: =SUM(E19:P19) -> 1570 | S19: 3100 | T19: 1570 | U19: =Q19-S19 -> -1530 | V19: =Q19-T19 -> 0
B20: REGULAR STARCH - Inco Sales (Export) | D20: MT | E20: =[62]Daily!AH155 -> 746.13 | F20: =[62]Daily!BK155 -> 1004.24 | G20: =[62]Daily!CQ155 -> 548 | H20: =[62]Daily!DV155 -> 1379 | I20: =[62]Daily!FB155 -> 1264 | J20: =[62]Daily!GG155 -> 477 | K20: =[62]Daily!HM155 -> 888 | L20: =[62]Daily!IS155 -> 1085 | M20: =[62]Daily!JX155 -> 896 | N20: =[62]Daily!LD155 -> 817 | O20: =[62]Daily!MI155 -> 985 | P20: =[62]Daily!NO155 -> 749 | Q20: =SUM(E20:P20) -> 10838.37 | S20: 9001.96 | T20: 10150.98 | U20: =Q20-S20 -> 1836.41 | V20: =Q20-T20 -> 687.39
B21: REGULAR STARCH - ISD Jumbo | D21: MT | E21: =[62]Daily!AH156 -> 0 | F21: =[62]Daily!BK156 -> 1309 | G21: =[62]Daily!CQ156 -> 655 | H21: =[62]Daily!DV156 -> 0 | I21: =[62]Daily!FB156 -> 1020 | J21: =[62]Daily!GG156 -> 493 | K21: =[62]Daily!HM156 -> 409 | L21: =[62]Daily!IS156 -> 955 | M21: =[62]Daily!JX156 -> 636 | N21: =[62]Daily!LD156 -> 153 | O21: =[62]Daily!MI156 -> 238 | P21: =[62]Daily!NO156 -> 0 | Q21: =SUM(E21:P21) -> 5868 | S21: 6160 | T21: 5681 | U21: =Q21-S21 -> -292 | V21: =Q21-T21 -> 187
B22: REGULAR STARCH - END Inv (in-house) | D22: MT | E22: =[62]Daily!AH159 -> 5015.77 | F22: =[62]Daily!BK159 -> 3893.9 | G22: =[62]Daily!CQ159 -> 4309.9 | H22: =[62]Daily!DV159 -> 3914.9 | I22: =[62]Daily!FB159 -> 2041.7969 | J22: =[62]Daily!GG159 -> 981.62897 | K22: =[62]Daily!HM159 -> 1205.6717 | L22: =[62]Daily!IS159 -> 1741.2707 | M22: =[62]Daily!JX159 -> 2055.8795 | N22: =[62]Daily!LD159 -> 2325.4764 | O22: =[62]Daily!MI159 -> 2503.5408 | P22: =[62]Daily!NO159 -> 1719.6595
B23: On hold stock | D23: MT | E23: =SUM([62]Daily!AH160:AH161) -> 485.46 | F23: =SUM([62]Daily!BK160:BK161) -> 1201 | G23: =SUM([62]Daily!CQ160:CQ161) -> 156.6 | H23: =SUM([62]Daily!DV160:DV161) -> 156.6 | I23: =SUM([62]Daily!FB160:FB161) -> 156.6 | J23: =SUM([62]Daily!GG160:GG161) -> 0 | K23: =SUM([62]Daily!HM160:HM161) -> 0 | L23: =SUM([62]Daily!IS160:IS161) -> 0 | M23: =SUM([62]Daily!JX160:JX161) -> 0 | N23: =SUM([62]Daily!LD160:LD161) -> 0 | O23: =SUM([62]Daily!MI160:MI161) -> 0 | P23: =SUM([62]Daily!NO160:NO161) -> 0
B24: REGULAR STARCH - SALEABLE INVENTORY | D24: MT | E24: =[62]Daily!AH164 -> 3976.83 | F24: =[62]Daily!BK164 -> 2660.9 | G24: =[62]Daily!CQ164 -> 4146.787 | H24: =[62]Daily!DV164 -> 3758.3 | I24: =[62]Daily!FB164 -> 1885.1969 | J24: =[62]Daily!GG164 -> 981.62897 | K24: =[62]Daily!HM164 -> 1205.6717 | L24: =[62]Daily!IS164 -> 1741.2707 | M24: =[62]Daily!JX164 -> 2055.8795 | N24: =[62]Daily!LD164 -> 2325.4764 | O24: =[62]Daily!MI164 -> 2503.5408 | P24: =[62]Daily!NO164 -> 1719.6595

Sheet Planner 29.4.2026
B2: Day operation | E2: 27 | F2: 28 | G2: 31 | H2: 24 | I2: 31 | J2: 30 | K2: 30 | L2: 31 | M2: 31 | N2: 31 | O2: 30 | P2: 26
B3: Average Regular Root Grinding/day in period no Grind Waxy | E3: 1340 | F3: 1200 | G3: 1210 | H3: 936 | I3: 1000 | J3: 1000 | K3: 1000 | L3: 1200 | M3: 1400 | N3: 1700 | O3: 1700 | P3: 1700
E4: Actual | F4: Actual | G4: Actual | H4: Actual+Plan | I4: Plan | J4: Plan | K4: Plan | L4: Plan | M4: Plan | N4: Plan | O4: Plan | P4: Plan
B5: Quarter | E5: Q1 | H5: Q2 | K5: Q3 | N5: Q4
B6: Month | D6: UOM | E6: Jan | F6: Feb | G6: Mar | H6: Apr | I6: May | J6: Jun | K6: Jul | L6: Aug | M6: Sep | N6: Oct | O6: Nov | P6: Dec | Q6: TOTAL | S6: LE0 2026 | T6: 3.2026 | U6: 04.2026 vs LE0 2026 | V6: 04.2026 vs 2.2026
B7: Regular Root Grinding Volume | D7: MT | E7: =[63]Daily!AH16 -> 29398 | F7: =[63]Daily!BK16 -> 30446.73 | G7: =[63]Daily!CQ16 -> 33527 | H7: =[63]Daily!DV16 -> 18622 | I7: =[63]Daily!FB16 -> 32289 | J7: =[63]Daily!GG16 -> 30000 | K7: =[63]Daily!HM16 -> 31000 | L7: =[63]Daily!IS16 -> 37200 | M7: =[63]Daily!JX16 -> 30250 | N7: =[63]Daily!LD16 -> 45300 | O7: =[63]Daily!MI16 -> 43650 | P7: =[63]Daily!NO16 -> 35100 | Q7: =SUM(E7:P7) -> 396782.73 | S7: 445200 | T7: 406714.32 | U7: =Q7-S7 -> -48417.27 | V7: =Q7-T7 -> -9931.5857
B8: Average Regular Root Grinding | D8: MT | E8: =[63]Daily!AH21 -> 1088.8148 | F8: =[63]Daily!BK21 -> 1087.3832 | G8: =[63]Daily!CQ21 -> 1081.5161 | H8: =[63]Daily!DV21 -> 775.91667 | I8: =[63]Daily!FB21 -> 1041.5806 | J8: =[63]Daily!GG21 -> 1000 | K8: =[63]Daily!HM21 -> 1000 | L8: =[63]Daily!IS21 -> 1200 | M8: =[63]Daily!JX21 -> 1008.3333 | N8: =[63]Daily!LD21 -> 1461.2903 | O8: =[63]Daily!MI21 -> 1455 | P8: =[63]Daily!NO21 -> 1350 | Q8: =AVERAGE(E8:P8) -> 1129.1529 | S8: 1271.0071 | T8: 1156.5823 | U8: =Q8-S8 -> -141.85417 | V8: =Q8-T8 -> -27.429418
B9: Regular PPDS | D9: THB/kg | E9: =[63]Daily!AH20 -> 10.41 | F9: =[63]Daily!BK20 -> 10.98 | G9: =[63]Daily!CQ20 -> 12 | H9: =[63]Daily!DV20 -> 15.42 | I9: =[63]Daily!FB20 -> 16.75 | J9: =[63]Daily!GG20 -> 12.166667 | K9: =[63]Daily!HM20 -> 12.94 | L9: =[63]Daily!IS20 -> 12.6 | M9: =[63]Daily!JX20 -> 12.3 | N9: =[63]Daily!LD20 -> 11.95 | O9: =[63]Daily!MI20 -> 11.73 | P9: =[63]Daily!NO20 -> 11.54 | U9: =Q9-S9 -> 0 | V9: =Q9-T9 -> 0
B10: Waxy Root Grinding Volume | D10: MT | E10: =[63]Daily!AH24 -> 2720 | F10: =[63]Daily!BK24 -> 2729 | G10: =[63]Daily!CQ24 -> 2114 | H10: =[63]Daily!DV24 -> 3794 | I10: =[63]Daily!FB24 -> 2900 | J10: =[63]Daily!GG24 -> 0 | K10: =[63]Daily!HM24 -> 0 | L10: =[63]Daily!IS24 -> 0 | M10: =[63]Daily!JX24 -> 0 | N10: =[63]Daily!LD24 -> 3000 | O10: =[63]Daily!MI24 -> 3000 | P10: =[63]Daily!NO24 -> 3000 | Q10: =SUM(E10:P10) -> 23257 | S10: 23876 | T10: 24147 | U10: =Q10-S10 -> -619 | V10: =Q10-T10 -> -890
B11: GLUCOSE - Sales | D11: MT | E11: =[63]Daily!AH99 -> 5234 | F11: =[63]Daily!BK99 -> 5504 | G11: =[63]Daily!CQ99 -> 5620 | H11: =[63]Daily!DV99 -> 3646 | I11: =[63]Daily!FB99 -> 3238 | J11: =[63]Daily!GG99 -> 5017 | K11: =[63]Daily!HM99 -> 5683 | L11: =[63]Daily!IS99 -> 5522 | M11: =[63]Daily!JX99 -> 5524 | N11: =[63]Daily!LD99 -> 5605 | O11: =[63]Daily!MI99 -> 5453 | P11: =[63]Daily!NO99 -> 5343 | Q11: =SUM(E11:P11) -> 61389 | S11: 66285.5 | T11: 64268 | U11: =Q11-S11 -> -4896.5 | V11: =Q11-T11 -> -2879
B12: HMS - Sales | D12: MT | E12: =[63]Daily!AH108 -> 570 | F12: =[63]Daily!BK108 -> 600 | G12: =[63]Daily!CQ108 -> 870 | H12: =[63]Daily!DV108 -> 750 | I12: =[63]Daily!FB108 -> 600 | J12: =[63]Daily!GG108 -> 594 | K12: =[63]Daily!HM108 -> 504 | L12: =[63]Daily!IS108 -> 503 | M12: =[63]Daily!JX108 -> 559 | N12: =[63]Daily!LD108 -> 708 | O12: =[63]Daily!MI108 -> 799 | P12: =[63]Daily!NO108 -> 804 | Q12: =SUM(E12:P12) -> 7861 | S12: 8220.3 | T12: 7662 | U12: =Q12-S12 -> -359.3 | V12: =Q12-T12 -> 199
B13: Total Glucose & HMS - Sales | D13: MT | E13: =E11+E12 -> 5804 | F13: =F11+F12 -> 6104 | G13: =G11+G12 -> 6490 | H13: =H11+H12 -> 4396 | I13: =I11+I12 -> 3838 | J13: =J11+J12 -> 5611 | K13: =K11+K12 -> 6187 | L13: =L11+L12 -> 6025 | ... P13: =P11+P12 -> 6147 | Q13: =SUM(E13:P13) -> 69250 | S13: 74505.8 | T13: 71930 | U13: =Q13-S13 -> -5255.8 | V13: =Q13-T13 -> -2680
B14: Stock Glucose Ending | D14: MT | E14: =[63]Daily!AH114 -> 973 | F14: =[63]Daily!BK114 -> 852 | G14: =[63]Daily!CQ114 -> 713 | H14: =[63]Daily!DV114 -> 711 | I14: =[63]Daily!FB114 -> 1003 | J14: =[63]Daily!GG114 -> 1092 | K14: =[63]Daily!HM114 -> 1105 | L14: =[63]Daily!IS114 -> 1080 | M14: =[63]Daily!JX114 -> 1097 | N14: =[63]Daily!LD114 -> 1084 | O14: =[63]Daily!MI114 -> 1132 | P14: =[63]Daily!NO114 -> 1285 | U14: =Q14-S14 -> 0 | V14: =Q14-T14 -> 0
B15: REGULAR STARCH - Production | D15: MT | E15: =[63]Daily!AH146 -> 2523.9 | F15: =[63]Daily!BK146 -> 2518.4233 | G15: =[63]Daily!CQ146 -> 2716.1 | H15: =[63]Daily!DV146 -> 254.2 | I15: =[63]Daily!FB146 -> 1778 | J15: =[63]Daily!GG146 -> 659.24228 | K15: =[63]Daily!HM146 -> 643.28196 | L15: =[63]Daily!IS146 -> 2548.4217 | M15: =[63]Daily!JX146 -> 1073.0538 | N15: =[63]Daily!LD146 -> 4700 | O15: =[63]Daily!MI146 -> 4253.144 | P15: =[63]Daily!NO146 -> 3250 | Q15: =SUM(E15:P15) -> 26917.767 | S15: 33406.027 | T15: 27182.309 | U15: =Q15-S15 -> -6488.2599 | V15: =Q15-T15 -> -264.54233
B16: REGULAR STARCH - in-house total Sales | D16: MT | E16: =[63]Daily!AH157 -> 2029.13 | F16: =[63]Daily!BK157 -> 4453.24 | G16: =[63]Daily!CQ157 -> 2012 | H16: =[63]Daily!DV157 -> 1802 | I16: =[63]Daily!FB157 -> 2967.76 | J16: =[63]Daily!GG157 -> 2037.91 | K16: =[63]Daily!HM157 -> 2260 | L16: =[63]Daily!IS157 -> 2845 | M16: =[63]Daily!JX157 -> 2366 | N16: =[63]Daily!LD157 -> 2396 | O16: =[63]Daily!MI157 -> 2854 | P16: =[63]Daily!NO157 -> 1983 | Q16: =SUM(E16:P16) -> 30006.04 | S16: 36370.34 | T16: 29460.99 | U16: =Q16-S16 -> -6364.3 | V16: =Q16-T16 -> 545.05
B17: REGULAR STARCH - 3P Export Sales | D17: MT | E17: =[63]Daily!AH152 -> 1094 | F17: =[63]Daily!BK152 -> 1940 | G17: =[63]Daily!CQ152 -> 537 | H17: =[63]Daily!DV152 -> 809 | I17: =[63]Daily!FB152 -> 301 | J17: =[63]Daily!GG152 -> 543 | K17: =[63]Daily!HM152 -> 595 | L17: =[63]Daily!IS152 -> 522 | M17: =[63]Daily!JX152 -> 579 | N17: =[63]Daily!LD152 -> 761 | O17: =[63]Daily!MI152 -> 693 | P17: =[63]Daily!NO152 -> 687 | Q17: =SUM(E17:P17) -> 9061 | S17: 15676.8 | T17: 8684 | U17: =Q17-S17 -> -6615.8 | V17: =Q17-T17 -> 377
B18: REGULAR STARCH - 3P Domestic Sales | D18: MT | E18: =[63]Daily!AH153 -> 189 | F18: =[63]Daily!BK153 -> 200 | G18: =[63]Daily!CQ153 -> 272 | H18: =[63]Daily!DV153 -> 145 | I18: =[63]Daily!FB153 -> 173 | J18: =[63]Daily!GG153 -> 208 | K18: =[63]Daily!HM153 -> 171 | L18: =[63]Daily!IS153 -> 173 | M18: =[63]Daily!JX153 -> 173 | N18: =[63]Daily!LD153 -> 204 | O18: =[63]Daily!MI153 -> 215 | P18: =[63]Daily!NO153 -> 198 | Q18: =SUM(E18:P18) -> 2321 | S18: 2431.58 | T18: 2399 | U18: =Q18-S18 -> -110.58 | V18: =Q18-T18 -> -78
